[2025-06-22T02:04:48.414+0000] {local_task_job_runner.py:120} INFO - ::group::Pre task execution logs
[2025-06-22T02:04:48.455+0000] {taskinstance.py:2076} INFO - Dependencies all met for dep_context=non-requeueable deps ti=<TaskInstance: etl_pipeline.load manual__2025-06-22T02:04:34.631237+00:00 [queued]>
[2025-06-22T02:04:48.469+0000] {taskinstance.py:2076} INFO - Dependencies all met for dep_context=requeueable deps ti=<TaskInstance: etl_pipeline.load manual__2025-06-22T02:04:34.631237+00:00 [queued]>
[2025-06-22T02:04:48.470+0000] {taskinstance.py:2306} INFO - Starting attempt 1 of 1
[2025-06-22T02:04:48.537+0000] {taskinstance.py:2330} INFO - Executing <Task(PythonOperator): load> on 2025-06-22 02:04:34.631237+00:00
[2025-06-22T02:04:48.546+0000] {standard_task_runner.py:90} INFO - Running: ['airflow', 'tasks', 'run', 'etl_pipeline', 'load', 'manual__2025-06-22T02:04:34.631237+00:00', '--job-id', '40', '--raw', '--subdir', 'DAGS_FOLDER/etl_dag.py', '--cfg-path', '/tmp/tmpeddpjui2']
[2025-06-22T02:04:48.550+0000] {standard_task_runner.py:91} INFO - Job 40: Subtask load
[2025-06-22T02:04:48.551+0000] {logging_mixin.py:188} WARNING - /home/airflow/.local/lib/python3.12/site-packages/airflow/task/task_runner/standard_task_runner.py:61 DeprecationWarning: This process (pid=46) is multi-threaded, use of fork() may lead to deadlocks in the child.
[2025-06-22T02:04:48.552+0000] {standard_task_runner.py:63} INFO - Started process 55 to run task
[2025-06-22T02:04:48.651+0000] {task_command.py:426} INFO - Running <TaskInstance: etl_pipeline.load manual__2025-06-22T02:04:34.631237+00:00 [running]> on host 8abbe489f871
[2025-06-22T02:04:48.838+0000] {taskinstance.py:2648} INFO - Exporting env vars: AIRFLOW_CTX_DAG_OWNER='airflow' AIRFLOW_CTX_DAG_ID='etl_pipeline' AIRFLOW_CTX_TASK_ID='load' AIRFLOW_CTX_EXECUTION_DATE='2025-06-22T02:04:34.631237+00:00' AIRFLOW_CTX_TRY_NUMBER='1' AIRFLOW_CTX_DAG_RUN_ID='manual__2025-06-22T02:04:34.631237+00:00'
[2025-06-22T02:04:48.840+0000] {taskinstance.py:430} INFO - ::endgroup::
[2025-06-22T02:04:48.856+0000] {TSocket.py:149} INFO - Could not connect to ('172.21.0.3', 10000)
Traceback (most recent call last):
  File "/home/airflow/.local/lib/python3.12/site-packages/thrift/transport/TSocket.py", line 144, in open
    handle.connect(sockaddr)
ConnectionRefusedError: [Errno 111] Connection refused
[2025-06-22T02:04:48.859+0000] {TSocket.py:152} ERROR - Could not connect to any of [('172.21.0.3', 10000)]
[2025-06-22T02:04:48.859+0000] {taskinstance.py:441} INFO - ::group::Post task execution logs
[2025-06-22T02:04:48.860+0000] {taskinstance.py:2905} ERROR - Task failed with exception
Traceback (most recent call last):
  File "/home/airflow/.local/lib/python3.12/site-packages/airflow/models/taskinstance.py", line 465, in _execute_task
    result = _execute_callable(context=context, **execute_callable_kwargs)
             ^^^^^^^^^^^^^^^^^^^^^^^^^^^^^^^^^^^^^^^^^^^^^^^^^^^^^^^^^^^^^
  File "/home/airflow/.local/lib/python3.12/site-packages/airflow/models/taskinstance.py", line 432, in _execute_callable
    return execute_callable(context=context, **execute_callable_kwargs)
           ^^^^^^^^^^^^^^^^^^^^^^^^^^^^^^^^^^^^^^^^^^^^^^^^^^^^^^^^^^^^
  File "/home/airflow/.local/lib/python3.12/site-packages/airflow/models/baseoperator.py", line 400, in wrapper
    return func(self, *args, **kwargs)
           ^^^^^^^^^^^^^^^^^^^^^^^^^^^
  File "/home/airflow/.local/lib/python3.12/site-packages/airflow/operators/python.py", line 235, in execute
    return_value = self.execute_callable()
                   ^^^^^^^^^^^^^^^^^^^^^^^
  File "/home/airflow/.local/lib/python3.12/site-packages/airflow/operators/python.py", line 252, in execute_callable
    return self.python_callable(*self.op_args, **self.op_kwargs)
           ^^^^^^^^^^^^^^^^^^^^^^^^^^^^^^^^^^^^^^^^^^^^^^^^^^^^^
  File "/opt/airflow/dags/scripts/load_to_hive.py", line 17, in load_to_hive
    conn = hive.Connection(host='hive-server', port=10000, username='hive')
           ^^^^^^^^^^^^^^^^^^^^^^^^^^^^^^^^^^^^^^^^^^^^^^^^^^^^^^^^^^^^^^^^
  File "/home/airflow/.local/lib/python3.12/site-packages/pyhive/hive.py", line 269, in __init__
    self._transport.open()
  File "/home/airflow/.local/lib/python3.12/site-packages/thrift_sasl/__init__.py", line 74, in open
    self._trans.open()
  File "/home/airflow/.local/lib/python3.12/site-packages/thrift/transport/TSocket.py", line 153, in open
    raise TTransportException(type=TTransportException.NOT_OPEN, message=msg)
thrift.transport.TTransport.TTransportException: Could not connect to any of [('172.21.0.3', 10000)]
[2025-06-22T02:04:48.874+0000] {taskinstance.py:1206} INFO - Marking task as FAILED. dag_id=etl_pipeline, task_id=load, run_id=manual__2025-06-22T02:04:34.631237+00:00, execution_date=20250622T020434, start_date=20250622T020448, end_date=20250622T020448
[2025-06-22T02:04:48.957+0000] {standard_task_runner.py:110} ERROR - Failed to execute job 40 for task load (Could not connect to any of [('172.21.0.3', 10000)]; 55)
[2025-06-22T02:04:48.969+0000] {local_task_job_runner.py:240} INFO - Task exited with return code 1
[2025-06-22T02:04:48.993+0000] {taskinstance.py:3498} INFO - 0 downstream tasks scheduled from follow-on schedule check
[2025-06-22T02:04:48.997+0000] {local_task_job_runner.py:222} INFO - ::endgroup::
