[2025-06-23T01:25:42.674+0000] {local_task_job_runner.py:120} INFO - ::group::Pre task execution logs
[2025-06-23T01:25:42.704+0000] {taskinstance.py:2076} INFO - Dependencies all met for dep_context=non-requeueable deps ti=<TaskInstance: etl_pipeline.transform manual__2025-06-23T01:25:07.336888+00:00 [queued]>
[2025-06-23T01:25:42.715+0000] {taskinstance.py:2076} INFO - Dependencies all met for dep_context=requeueable deps ti=<TaskInstance: etl_pipeline.transform manual__2025-06-23T01:25:07.336888+00:00 [queued]>
[2025-06-23T01:25:42.716+0000] {taskinstance.py:2306} INFO - Starting attempt 1 of 1
[2025-06-23T01:25:42.745+0000] {taskinstance.py:2330} INFO - Executing <Task(PythonOperator): transform> on 2025-06-23 01:25:07.336888+00:00
[2025-06-23T01:25:42.763+0000] {logging_mixin.py:188} WARNING - /home/airflow/.local/lib/python3.12/site-packages/airflow/task/task_runner/standard_task_runner.py:61 DeprecationWarning: This process (pid=515) is multi-threaded, use of fork() may lead to deadlocks in the child.
[2025-06-23T01:25:42.758+0000] {standard_task_runner.py:90} INFO - Running: ['airflow', 'tasks', 'run', 'etl_pipeline', 'transform', 'manual__2025-06-23T01:25:07.336888+00:00', '--job-id', '184', '--raw', '--subdir', 'DAGS_FOLDER/etl_dag.py', '--cfg-path', '/tmp/tmpxvnh7lpd']
[2025-06-23T01:25:42.764+0000] {standard_task_runner.py:63} INFO - Started process 524 to run task
[2025-06-23T01:25:42.764+0000] {standard_task_runner.py:91} INFO - Job 184: Subtask transform
[2025-06-23T01:25:42.873+0000] {task_command.py:426} INFO - Running <TaskInstance: etl_pipeline.transform manual__2025-06-23T01:25:07.336888+00:00 [running]> on host 4fb827bf51e5
[2025-06-23T01:25:42.967+0000] {taskinstance.py:2648} INFO - Exporting env vars: AIRFLOW_CTX_DAG_OWNER='airflow' AIRFLOW_CTX_DAG_ID='etl_pipeline' AIRFLOW_CTX_TASK_ID='transform' AIRFLOW_CTX_EXECUTION_DATE='2025-06-23T01:25:07.336888+00:00' AIRFLOW_CTX_TRY_NUMBER='1' AIRFLOW_CTX_DAG_RUN_ID='manual__2025-06-23T01:25:07.336888+00:00'
[2025-06-23T01:25:42.969+0000] {taskinstance.py:430} INFO - ::endgroup::
[2025-06-23T01:25:48.983+0000] {taskinstance.py:441} INFO - ::group::Post task execution logs
[2025-06-23T01:25:48.985+0000] {taskinstance.py:2905} ERROR - Task failed with exception
Traceback (most recent call last):
  File "/home/airflow/.local/lib/python3.12/site-packages/airflow/models/taskinstance.py", line 465, in _execute_task
    result = _execute_callable(context=context, **execute_callable_kwargs)
             ^^^^^^^^^^^^^^^^^^^^^^^^^^^^^^^^^^^^^^^^^^^^^^^^^^^^^^^^^^^^^
  File "/home/airflow/.local/lib/python3.12/site-packages/airflow/models/taskinstance.py", line 432, in _execute_callable
    return execute_callable(context=context, **execute_callable_kwargs)
           ^^^^^^^^^^^^^^^^^^^^^^^^^^^^^^^^^^^^^^^^^^^^^^^^^^^^^^^^^^^^
  File "/home/airflow/.local/lib/python3.12/site-packages/airflow/models/baseoperator.py", line 400, in wrapper
    return func(self, *args, **kwargs)
           ^^^^^^^^^^^^^^^^^^^^^^^^^^^
  File "/home/airflow/.local/lib/python3.12/site-packages/airflow/operators/python.py", line 235, in execute
    return_value = self.execute_callable()
                   ^^^^^^^^^^^^^^^^^^^^^^^
  File "/home/airflow/.local/lib/python3.12/site-packages/airflow/operators/python.py", line 252, in execute_callable
    return self.python_callable(*self.op_args, **self.op_kwargs)
           ^^^^^^^^^^^^^^^^^^^^^^^^^^^^^^^^^^^^^^^^^^^^^^^^^^^^^
  File "/opt/airflow/dags/scripts/transform_with_spark.py", line 20, in transform_with_spark
    df = spark.read.csv("/opt/airflow/dags/users.csv", header=True, inferSchema=True)
         ^^^^^^^^^^^^^^^^^^^^^^^^^^^^^^^^^^^^^^^^^^^^^^^^^^^^^^^^^^^^^^^^^^^^^^^^^^^^
  File "/home/airflow/.local/lib/python3.12/site-packages/pyspark/sql/readwriter.py", line 838, in csv
    return self._df(self._jreader.csv(self._spark._sc._jvm.PythonUtils.toSeq(path)))
                    ^^^^^^^^^^^^^^^^^^^^^^^^^^^^^^^^^^^^^^^^^^^^^^^^^^^^^^^^^^^^^^^
  File "/home/airflow/.local/lib/python3.12/site-packages/py4j/java_gateway.py", line 1362, in __call__
    return_value = get_return_value(
                   ^^^^^^^^^^^^^^^^^
  File "/home/airflow/.local/lib/python3.12/site-packages/pyspark/errors/exceptions/captured.py", line 288, in deco
    raise converted from None
pyspark.errors.exceptions.captured.AnalysisException: [PATH_NOT_FOUND] Path does not exist: file:/opt/airflow/dags/users.csv. SQLSTATE: 42K03
[2025-06-23T01:25:49.011+0000] {taskinstance.py:1206} INFO - Marking task as FAILED. dag_id=etl_pipeline, task_id=transform, run_id=manual__2025-06-23T01:25:07.336888+00:00, execution_date=20250623T012507, start_date=20250623T012542, end_date=20250623T012549
[2025-06-23T01:25:49.045+0000] {standard_task_runner.py:110} ERROR - Failed to execute job 184 for task transform ([PATH_NOT_FOUND] Path does not exist: file:/opt/airflow/dags/users.csv. SQLSTATE: 42K03; 524)
[2025-06-23T01:25:49.096+0000] {local_task_job_runner.py:240} INFO - Task exited with return code 1
[2025-06-23T01:25:49.129+0000] {taskinstance.py:3498} INFO - 0 downstream tasks scheduled from follow-on schedule check
[2025-06-23T01:25:49.153+0000] {local_task_job_runner.py:222} INFO - ::endgroup::
