[2025-06-22T02:39:37.439+0000] {local_task_job_runner.py:120} INFO - ::group::Pre task execution logs
[2025-06-22T02:39:37.468+0000] {taskinstance.py:2076} INFO - Dependencies all met for dep_context=non-requeueable deps ti=<TaskInstance: etl_pipeline.load manual__2025-06-22T02:39:26.463197+00:00 [queued]>
[2025-06-22T02:39:37.479+0000] {taskinstance.py:2076} INFO - Dependencies all met for dep_context=requeueable deps ti=<TaskInstance: etl_pipeline.load manual__2025-06-22T02:39:26.463197+00:00 [queued]>
[2025-06-22T02:39:37.480+0000] {taskinstance.py:2306} INFO - Starting attempt 1 of 1
[2025-06-22T02:39:37.556+0000] {taskinstance.py:2330} INFO - Executing <Task(PythonOperator): load> on 2025-06-22 02:39:26.463197+00:00
[2025-06-22T02:39:37.563+0000] {standard_task_runner.py:90} INFO - Running: ['airflow', 'tasks', 'run', 'etl_pipeline', 'load', 'manual__2025-06-22T02:39:26.463197+00:00', '--job-id', '51', '--raw', '--subdir', 'DAGS_FOLDER/etl_dag.py', '--cfg-path', '/tmp/tmpozy25zse']
[2025-06-22T02:39:37.566+0000] {standard_task_runner.py:91} INFO - Job 51: Subtask load
[2025-06-22T02:39:37.567+0000] {logging_mixin.py:188} WARNING - /home/airflow/.local/lib/python3.12/site-packages/airflow/task/task_runner/standard_task_runner.py:61 DeprecationWarning: This process (pid=53) is multi-threaded, use of fork() may lead to deadlocks in the child.
[2025-06-22T02:39:37.568+0000] {standard_task_runner.py:63} INFO - Started process 62 to run task
[2025-06-22T02:39:37.688+0000] {task_command.py:426} INFO - Running <TaskInstance: etl_pipeline.load manual__2025-06-22T02:39:26.463197+00:00 [running]> on host ff90f94b72f1
[2025-06-22T02:39:37.804+0000] {taskinstance.py:2648} INFO - Exporting env vars: AIRFLOW_CTX_DAG_OWNER='airflow' AIRFLOW_CTX_DAG_ID='etl_pipeline' AIRFLOW_CTX_TASK_ID='load' AIRFLOW_CTX_EXECUTION_DATE='2025-06-22T02:39:26.463197+00:00' AIRFLOW_CTX_TRY_NUMBER='1' AIRFLOW_CTX_DAG_RUN_ID='manual__2025-06-22T02:39:26.463197+00:00'
[2025-06-22T02:39:37.805+0000] {taskinstance.py:430} INFO - ::endgroup::
[2025-06-22T02:39:38.076+0000] {hive.py:475} INFO - USE `default`
[2025-06-22T02:39:39.015+0000] {logging_mixin.py:188} INFO - Cargando tabla: menu desde /opt/airflow/dags/menu.csv
[2025-06-22T02:39:39.029+0000] {hive.py:475} INFO - 
                CREATE TABLE IF NOT EXISTS menu (
                    menu_id INT, Name STRING
                )
                ROW FORMAT DELIMITED
                FIELDS TERMINATED BY ','
                STORED AS TEXTFILE
            
[2025-06-22T02:39:40.308+0000] {taskinstance.py:441} INFO - ::group::Post task execution logs
[2025-06-22T02:39:40.309+0000] {taskinstance.py:2905} ERROR - Task failed with exception
Traceback (most recent call last):
  File "/home/airflow/.local/lib/python3.12/site-packages/airflow/models/taskinstance.py", line 465, in _execute_task
    result = _execute_callable(context=context, **execute_callable_kwargs)
             ^^^^^^^^^^^^^^^^^^^^^^^^^^^^^^^^^^^^^^^^^^^^^^^^^^^^^^^^^^^^^
  File "/home/airflow/.local/lib/python3.12/site-packages/airflow/models/taskinstance.py", line 432, in _execute_callable
    return execute_callable(context=context, **execute_callable_kwargs)
           ^^^^^^^^^^^^^^^^^^^^^^^^^^^^^^^^^^^^^^^^^^^^^^^^^^^^^^^^^^^^
  File "/home/airflow/.local/lib/python3.12/site-packages/airflow/models/baseoperator.py", line 400, in wrapper
    return func(self, *args, **kwargs)
           ^^^^^^^^^^^^^^^^^^^^^^^^^^^
  File "/home/airflow/.local/lib/python3.12/site-packages/airflow/operators/python.py", line 235, in execute
    return_value = self.execute_callable()
                   ^^^^^^^^^^^^^^^^^^^^^^^
  File "/home/airflow/.local/lib/python3.12/site-packages/airflow/operators/python.py", line 252, in execute_callable
    return self.python_callable(*self.op_args, **self.op_kwargs)
           ^^^^^^^^^^^^^^^^^^^^^^^^^^^^^^^^^^^^^^^^^^^^^^^^^^^^^
  File "/opt/airflow/dags/scripts/load_to_hive.py", line 48, in load_to_hive
    subprocess.run([
  File "/usr/local/lib/python3.12/subprocess.py", line 571, in run
    raise CalledProcessError(retcode, process.args,
subprocess.CalledProcessError: Command '['docker', 'cp', '/opt/airflow/dags/menu.csv', 'hive-server:/tmp/menu.csv']' returned non-zero exit status 1.
[2025-06-22T02:39:40.319+0000] {taskinstance.py:1206} INFO - Marking task as FAILED. dag_id=etl_pipeline, task_id=load, run_id=manual__2025-06-22T02:39:26.463197+00:00, execution_date=20250622T023926, start_date=20250622T023937, end_date=20250622T023940
[2025-06-22T02:39:40.385+0000] {standard_task_runner.py:110} ERROR - Failed to execute job 51 for task load (Command '['docker', 'cp', '/opt/airflow/dags/menu.csv', 'hive-server:/tmp/menu.csv']' returned non-zero exit status 1.; 62)
[2025-06-22T02:39:40.395+0000] {local_task_job_runner.py:240} INFO - Task exited with return code 1
[2025-06-22T02:39:40.417+0000] {taskinstance.py:3498} INFO - 0 downstream tasks scheduled from follow-on schedule check
[2025-06-22T02:39:40.418+0000] {local_task_job_runner.py:222} INFO - ::endgroup::
