[2025-06-22T03:05:28.802+0000] {local_task_job_runner.py:120} INFO - ::group::Pre task execution logs
[2025-06-22T03:05:28.842+0000] {taskinstance.py:2076} INFO - Dependencies all met for dep_context=non-requeueable deps ti=<TaskInstance: etl_pipeline.load manual__2025-06-22T03:05:20.783630+00:00 [queued]>
[2025-06-22T03:05:28.873+0000] {taskinstance.py:2076} INFO - Dependencies all met for dep_context=requeueable deps ti=<TaskInstance: etl_pipeline.load manual__2025-06-22T03:05:20.783630+00:00 [queued]>
[2025-06-22T03:05:28.874+0000] {taskinstance.py:2306} INFO - Starting attempt 1 of 1
[2025-06-22T03:05:28.925+0000] {taskinstance.py:2330} INFO - Executing <Task(PythonOperator): load> on 2025-06-22 03:05:20.783630+00:00
[2025-06-22T03:05:28.932+0000] {standard_task_runner.py:90} INFO - Running: ['airflow', 'tasks', 'run', 'etl_pipeline', 'load', 'manual__2025-06-22T03:05:20.783630+00:00', '--job-id', '63', '--raw', '--subdir', 'DAGS_FOLDER/etl_dag.py', '--cfg-path', '/tmp/tmpuq6i66b8']
[2025-06-22T03:05:28.935+0000] {standard_task_runner.py:91} INFO - Job 63: Subtask load
[2025-06-22T03:05:28.938+0000] {logging_mixin.py:188} WARNING - /home/airflow/.local/lib/python3.12/site-packages/airflow/task/task_runner/standard_task_runner.py:61 DeprecationWarning: This process (pid=78) is multi-threaded, use of fork() may lead to deadlocks in the child.
[2025-06-22T03:05:28.939+0000] {standard_task_runner.py:63} INFO - Started process 87 to run task
[2025-06-22T03:05:29.010+0000] {task_command.py:426} INFO - Running <TaskInstance: etl_pipeline.load manual__2025-06-22T03:05:20.783630+00:00 [running]> on host e50997d0952b
[2025-06-22T03:05:29.371+0000] {taskinstance.py:2648} INFO - Exporting env vars: AIRFLOW_CTX_DAG_OWNER='airflow' AIRFLOW_CTX_DAG_ID='etl_pipeline' AIRFLOW_CTX_TASK_ID='load' AIRFLOW_CTX_EXECUTION_DATE='2025-06-22T03:05:20.783630+00:00' AIRFLOW_CTX_TRY_NUMBER='1' AIRFLOW_CTX_DAG_RUN_ID='manual__2025-06-22T03:05:20.783630+00:00'
[2025-06-22T03:05:29.373+0000] {taskinstance.py:430} INFO - ::endgroup::
[2025-06-22T03:05:29.543+0000] {hive.py:475} INFO - USE `default`
[2025-06-22T03:05:29.686+0000] {logging_mixin.py:188} INFO - Cargando tabla: menu desde /opt/airflow/dags/menu.csv
[2025-06-22T03:05:29.707+0000] {hive.py:475} INFO - 
                CREATE TABLE IF NOT EXISTS menu (
                    menu_id INT, Name STRING
                )
                ROW FORMAT DELIMITED
                FIELDS TERMINATED BY ','
                STORED AS TEXTFILE
            
[2025-06-22T03:05:29.747+0000] {hive.py:475} INFO - LOAD DATA LOCAL INPATH '/opt/airflow/dags/menu.csv' OVERWRITE INTO TABLE menu
[2025-06-22T03:05:30.607+0000] {logging_mixin.py:188} INFO - Cargando tabla: menu_restaurant desde /opt/airflow/dags/menu_restaurant.csv
[2025-06-22T03:05:30.616+0000] {hive.py:475} INFO - 
                CREATE TABLE IF NOT EXISTS menu_restaurant (
                    restaurant_id INT, menu_id INT
                )
                ROW FORMAT DELIMITED
                FIELDS TERMINATED BY ','
                STORED AS TEXTFILE
            
[2025-06-22T03:05:30.702+0000] {hive.py:475} INFO - LOAD DATA LOCAL INPATH '/opt/airflow/dags/menu_restaurant.csv' OVERWRITE INTO TABLE menu_restaurant
[2025-06-22T03:05:31.078+0000] {logging_mixin.py:188} INFO - Cargando tabla: Order desde /opt/airflow/dags/Order.csv
[2025-06-22T03:05:31.084+0000] {hive.py:475} INFO - 
                CREATE TABLE IF NOT EXISTS Order (
                    order_id INT, Datetime STRING, user_id INT, restaurant_id INT, Address STRING, Status STRING
                )
                ROW FORMAT DELIMITED
                FIELDS TERMINATED BY ','
                STORED AS TEXTFILE
            
[2025-06-22T03:05:31.092+0000] {taskinstance.py:441} INFO - ::group::Post task execution logs
[2025-06-22T03:05:31.094+0000] {taskinstance.py:2905} ERROR - Task failed with exception
Traceback (most recent call last):
  File "/home/airflow/.local/lib/python3.12/site-packages/airflow/models/taskinstance.py", line 465, in _execute_task
    result = _execute_callable(context=context, **execute_callable_kwargs)
             ^^^^^^^^^^^^^^^^^^^^^^^^^^^^^^^^^^^^^^^^^^^^^^^^^^^^^^^^^^^^^
  File "/home/airflow/.local/lib/python3.12/site-packages/airflow/models/taskinstance.py", line 432, in _execute_callable
    return execute_callable(context=context, **execute_callable_kwargs)
           ^^^^^^^^^^^^^^^^^^^^^^^^^^^^^^^^^^^^^^^^^^^^^^^^^^^^^^^^^^^^
  File "/home/airflow/.local/lib/python3.12/site-packages/airflow/models/baseoperator.py", line 400, in wrapper
    return func(self, *args, **kwargs)
           ^^^^^^^^^^^^^^^^^^^^^^^^^^^
  File "/home/airflow/.local/lib/python3.12/site-packages/airflow/operators/python.py", line 235, in execute
    return_value = self.execute_callable()
                   ^^^^^^^^^^^^^^^^^^^^^^^
  File "/home/airflow/.local/lib/python3.12/site-packages/airflow/operators/python.py", line 252, in execute_callable
    return self.python_callable(*self.op_args, **self.op_kwargs)
           ^^^^^^^^^^^^^^^^^^^^^^^^^^^^^^^^^^^^^^^^^^^^^^^^^^^^^
  File "/opt/airflow/dags/scripts/load_to_hive.py", line 40, in load_to_hive
    cursor.execute(f"""
  File "/home/airflow/.local/lib/python3.12/site-packages/pyhive/hive.py", line 481, in execute
    _check_status(response)
  File "/home/airflow/.local/lib/python3.12/site-packages/pyhive/hive.py", line 611, in _check_status
    raise OperationalError(response)
pyhive.exc.OperationalError: TExecuteStatementResp(status=TStatus(statusCode=3, infoMessages=["*org.apache.hive.service.cli.HiveSQLException:Error while compiling statement: FAILED: ParseException line 2:43 cannot recognize input near 'Order' '(' 'order_id' in table name:17:16", 'org.apache.hive.service.cli.operation.Operation:toSQLException:Operation.java:380', 'org.apache.hive.service.cli.operation.SQLOperation:prepare:SQLOperation.java:206', 'org.apache.hive.service.cli.operation.SQLOperation:runInternal:SQLOperation.java:290', 'org.apache.hive.service.cli.operation.Operation:run:Operation.java:320', 'org.apache.hive.service.cli.session.HiveSessionImpl:executeStatementInternal:HiveSessionImpl.java:530', 'org.apache.hive.service.cli.session.HiveSessionImpl:executeStatement:HiveSessionImpl.java:506', 'org.apache.hive.service.cli.CLIService:executeStatement:CLIService.java:280', 'org.apache.hive.service.cli.thrift.ThriftCLIService:ExecuteStatement:ThriftCLIService.java:531', 'org.apache.hive.service.rpc.thrift.TCLIService$Processor$ExecuteStatement:getResult:TCLIService.java:1437', 'org.apache.hive.service.rpc.thrift.TCLIService$Processor$ExecuteStatement:getResult:TCLIService.java:1422', 'org.apache.thrift.ProcessFunction:process:ProcessFunction.java:39', 'org.apache.thrift.TBaseProcessor:process:TBaseProcessor.java:39', 'org.apache.hive.service.auth.TSetIpAddressProcessor:process:TSetIpAddressProcessor.java:56', 'org.apache.thrift.server.TThreadPoolServer$WorkerProcess:run:TThreadPoolServer.java:286', 'java.util.concurrent.ThreadPoolExecutor:runWorker:ThreadPoolExecutor.java:1142', 'java.util.concurrent.ThreadPoolExecutor$Worker:run:ThreadPoolExecutor.java:617', 'java.lang.Thread:run:Thread.java:748', "*org.apache.hadoop.hive.ql.parse.ParseException:line 2:43 cannot recognize input near 'Order' '(' 'order_id' in table name:22:6", 'org.apache.hadoop.hive.ql.parse.ParseDriver:parse:ParseDriver.java:211', 'org.apache.hadoop.hive.ql.parse.ParseUtils:parse:ParseUtils.java:77', 'org.apache.hadoop.hive.ql.parse.ParseUtils:parse:ParseUtils.java:70', 'org.apache.hadoop.hive.ql.Driver:compile:Driver.java:468', 'org.apache.hadoop.hive.ql.Driver:compileInternal:Driver.java:1317', 'org.apache.hadoop.hive.ql.Driver:compileAndRespond:Driver.java:1295', 'org.apache.hive.service.cli.operation.SQLOperation:prepare:SQLOperation.java:204'], sqlState='42000', errorCode=40000, errorMessage="Error while compiling statement: FAILED: ParseException line 2:43 cannot recognize input near 'Order' '(' 'order_id' in table name"), operationHandle=None)
[2025-06-22T03:05:31.116+0000] {taskinstance.py:1206} INFO - Marking task as FAILED. dag_id=etl_pipeline, task_id=load, run_id=manual__2025-06-22T03:05:20.783630+00:00, execution_date=20250622T030520, start_date=20250622T030528, end_date=20250622T030531
[2025-06-22T03:05:31.141+0000] {standard_task_runner.py:110} ERROR - Failed to execute job 63 for task load (TExecuteStatementResp(status=TStatus(statusCode=3, infoMessages=["*org.apache.hive.service.cli.HiveSQLException:Error while compiling statement: FAILED: ParseException line 2:43 cannot recognize input near 'Order' '(' 'order_id' in table name:17:16", 'org.apache.hive.service.cli.operation.Operation:toSQLException:Operation.java:380', 'org.apache.hive.service.cli.operation.SQLOperation:prepare:SQLOperation.java:206', 'org.apache.hive.service.cli.operation.SQLOperation:runInternal:SQLOperation.java:290', 'org.apache.hive.service.cli.operation.Operation:run:Operation.java:320', 'org.apache.hive.service.cli.session.HiveSessionImpl:executeStatementInternal:HiveSessionImpl.java:530', 'org.apache.hive.service.cli.session.HiveSessionImpl:executeStatement:HiveSessionImpl.java:506', 'org.apache.hive.service.cli.CLIService:executeStatement:CLIService.java:280', 'org.apache.hive.service.cli.thrift.ThriftCLIService:ExecuteStatement:ThriftCLIService.java:531', 'org.apache.hive.service.rpc.thrift.TCLIService$Processor$ExecuteStatement:getResult:TCLIService.java:1437', 'org.apache.hive.service.rpc.thrift.TCLIService$Processor$ExecuteStatement:getResult:TCLIService.java:1422', 'org.apache.thrift.ProcessFunction:process:ProcessFunction.java:39', 'org.apache.thrift.TBaseProcessor:process:TBaseProcessor.java:39', 'org.apache.hive.service.auth.TSetIpAddressProcessor:process:TSetIpAddressProcessor.java:56', 'org.apache.thrift.server.TThreadPoolServer$WorkerProcess:run:TThreadPoolServer.java:286', 'java.util.concurrent.ThreadPoolExecutor:runWorker:ThreadPoolExecutor.java:1142', 'java.util.concurrent.ThreadPoolExecutor$Worker:run:ThreadPoolExecutor.java:617', 'java.lang.Thread:run:Thread.java:748', "*org.apache.hadoop.hive.ql.parse.ParseException:line 2:43 cannot recognize input near 'Order' '(' 'order_id' in table name:22:6", 'org.apache.hadoop.hive.ql.parse.ParseDriver:parse:ParseDriver.java:211', 'org.apache.hadoop.hive.ql.parse.ParseUtils:parse:ParseUtils.java:77', 'org.apache.hadoop.hive.ql.parse.ParseUtils:parse:ParseUtils.java:70', 'org.apache.hadoop.hive.ql.Driver:compile:Driver.java:468', 'org.apache.hadoop.hive.ql.Driver:compileInternal:Driver.java:1317', 'org.apache.hadoop.hive.ql.Driver:compileAndRespond:Driver.java:1295', 'org.apache.hive.service.cli.operation.SQLOperation:prepare:SQLOperation.java:204'], sqlState='42000', errorCode=40000, errorMessage="Error while compiling statement: FAILED: ParseException line 2:43 cannot recognize input near 'Order' '(' 'order_id' in table name"), operationHandle=None); 87)
[2025-06-22T03:05:31.167+0000] {local_task_job_runner.py:240} INFO - Task exited with return code 1
[2025-06-22T03:05:31.185+0000] {taskinstance.py:3498} INFO - 0 downstream tasks scheduled from follow-on schedule check
[2025-06-22T03:05:31.186+0000] {local_task_job_runner.py:222} INFO - ::endgroup::
