[2025-06-22T01:44:29.809+0000] {local_task_job_runner.py:120} INFO - ::group::Pre task execution logs
[2025-06-22T01:44:29.843+0000] {taskinstance.py:2076} INFO - Dependencies all met for dep_context=non-requeueable deps ti=<TaskInstance: etl_pipeline.load manual__2025-06-22T01:44:13.832255+00:00 [queued]>
[2025-06-22T01:44:29.856+0000] {taskinstance.py:2076} INFO - Dependencies all met for dep_context=requeueable deps ti=<TaskInstance: etl_pipeline.load manual__2025-06-22T01:44:13.832255+00:00 [queued]>
[2025-06-22T01:44:29.857+0000] {taskinstance.py:2306} INFO - Starting attempt 1 of 1
[2025-06-22T01:44:29.906+0000] {taskinstance.py:2330} INFO - Executing <Task(PythonOperator): load> on 2025-06-22 01:44:13.832255+00:00
[2025-06-22T01:44:29.915+0000] {standard_task_runner.py:90} INFO - Running: ['airflow', 'tasks', 'run', 'etl_pipeline', 'load', 'manual__2025-06-22T01:44:13.832255+00:00', '--job-id', '29', '--raw', '--subdir', 'DAGS_FOLDER/etl_dag.py', '--cfg-path', '/tmp/tmpsi8ethjp']
[2025-06-22T01:44:29.918+0000] {standard_task_runner.py:91} INFO - Job 29: Subtask load
[2025-06-22T01:44:29.920+0000] {logging_mixin.py:188} WARNING - /home/airflow/.local/lib/python3.12/site-packages/airflow/task/task_runner/standard_task_runner.py:61 DeprecationWarning: This process (pid=54) is multi-threaded, use of fork() may lead to deadlocks in the child.
[2025-06-22T01:44:29.921+0000] {standard_task_runner.py:63} INFO - Started process 63 to run task
[2025-06-22T01:44:30.051+0000] {task_command.py:426} INFO - Running <TaskInstance: etl_pipeline.load manual__2025-06-22T01:44:13.832255+00:00 [running]> on host 9113e37d6778
[2025-06-22T01:44:30.242+0000] {taskinstance.py:2648} INFO - Exporting env vars: AIRFLOW_CTX_DAG_OWNER='airflow' AIRFLOW_CTX_DAG_ID='etl_pipeline' AIRFLOW_CTX_TASK_ID='load' AIRFLOW_CTX_EXECUTION_DATE='2025-06-22T01:44:13.832255+00:00' AIRFLOW_CTX_TRY_NUMBER='1' AIRFLOW_CTX_DAG_RUN_ID='manual__2025-06-22T01:44:13.832255+00:00'
[2025-06-22T01:44:30.243+0000] {taskinstance.py:430} INFO - ::endgroup::
[2025-06-22T01:44:34.096+0000] {TSocket.py:133} ERROR - failed to resolve sockaddr for hive-server:10000
Traceback (most recent call last):
  File "/home/airflow/.local/lib/python3.12/site-packages/thrift/transport/TSocket.py", line 130, in open
    addrs = self._resolveAddr()
            ^^^^^^^^^^^^^^^^^^^
  File "/home/airflow/.local/lib/python3.12/site-packages/thrift/transport/TSocket.py", line 37, in _resolveAddr
    return socket.getaddrinfo(self.host,
           ^^^^^^^^^^^^^^^^^^^^^^^^^^^^^
  File "/usr/local/lib/python3.12/socket.py", line 963, in getaddrinfo
    for res in _socket.getaddrinfo(host, port, family, type, proto, flags):
               ^^^^^^^^^^^^^^^^^^^^^^^^^^^^^^^^^^^^^^^^^^^^^^^^^^^^^^^^^^^
socket.gaierror: [Errno -2] Name or service not known
[2025-06-22T01:44:34.101+0000] {taskinstance.py:441} INFO - ::group::Post task execution logs
[2025-06-22T01:44:34.102+0000] {taskinstance.py:2905} ERROR - Task failed with exception
Traceback (most recent call last):
  File "/home/airflow/.local/lib/python3.12/site-packages/thrift/transport/TSocket.py", line 130, in open
    addrs = self._resolveAddr()
            ^^^^^^^^^^^^^^^^^^^
  File "/home/airflow/.local/lib/python3.12/site-packages/thrift/transport/TSocket.py", line 37, in _resolveAddr
    return socket.getaddrinfo(self.host,
           ^^^^^^^^^^^^^^^^^^^^^^^^^^^^^
  File "/usr/local/lib/python3.12/socket.py", line 963, in getaddrinfo
    for res in _socket.getaddrinfo(host, port, family, type, proto, flags):
               ^^^^^^^^^^^^^^^^^^^^^^^^^^^^^^^^^^^^^^^^^^^^^^^^^^^^^^^^^^^
socket.gaierror: [Errno -2] Name or service not known

During handling of the above exception, another exception occurred:

Traceback (most recent call last):
  File "/home/airflow/.local/lib/python3.12/site-packages/airflow/models/taskinstance.py", line 465, in _execute_task
    result = _execute_callable(context=context, **execute_callable_kwargs)
             ^^^^^^^^^^^^^^^^^^^^^^^^^^^^^^^^^^^^^^^^^^^^^^^^^^^^^^^^^^^^^
  File "/home/airflow/.local/lib/python3.12/site-packages/airflow/models/taskinstance.py", line 432, in _execute_callable
    return execute_callable(context=context, **execute_callable_kwargs)
           ^^^^^^^^^^^^^^^^^^^^^^^^^^^^^^^^^^^^^^^^^^^^^^^^^^^^^^^^^^^^
  File "/home/airflow/.local/lib/python3.12/site-packages/airflow/models/baseoperator.py", line 400, in wrapper
    return func(self, *args, **kwargs)
           ^^^^^^^^^^^^^^^^^^^^^^^^^^^
  File "/home/airflow/.local/lib/python3.12/site-packages/airflow/operators/python.py", line 235, in execute
    return_value = self.execute_callable()
                   ^^^^^^^^^^^^^^^^^^^^^^^
  File "/home/airflow/.local/lib/python3.12/site-packages/airflow/operators/python.py", line 252, in execute_callable
    return self.python_callable(*self.op_args, **self.op_kwargs)
           ^^^^^^^^^^^^^^^^^^^^^^^^^^^^^^^^^^^^^^^^^^^^^^^^^^^^^
  File "/opt/airflow/dags/scripts/load_to_hive.py", line 17, in load_to_hive
    conn = hive.Connection(host='hive-server', port=10000, username='hive')
           ^^^^^^^^^^^^^^^^^^^^^^^^^^^^^^^^^^^^^^^^^^^^^^^^^^^^^^^^^^^^^^^^
  File "/home/airflow/.local/lib/python3.12/site-packages/pyhive/hive.py", line 269, in __init__
    self._transport.open()
  File "/home/airflow/.local/lib/python3.12/site-packages/thrift_sasl/__init__.py", line 74, in open
    self._trans.open()
  File "/home/airflow/.local/lib/python3.12/site-packages/thrift/transport/TSocket.py", line 134, in open
    raise TTransportException(type=TTransportException.NOT_OPEN, message=msg, inner=gai)
thrift.transport.TTransport.TTransportException: failed to resolve sockaddr for hive-server:10000
[2025-06-22T01:44:34.122+0000] {taskinstance.py:1206} INFO - Marking task as FAILED. dag_id=etl_pipeline, task_id=load, run_id=manual__2025-06-22T01:44:13.832255+00:00, execution_date=20250622T014413, start_date=20250622T014429, end_date=20250622T014434
[2025-06-22T01:44:34.201+0000] {standard_task_runner.py:110} ERROR - Failed to execute job 29 for task load (failed to resolve sockaddr for hive-server:10000; 63)
[2025-06-22T01:44:34.232+0000] {local_task_job_runner.py:240} INFO - Task exited with return code 1
[2025-06-22T01:44:34.258+0000] {taskinstance.py:3498} INFO - 0 downstream tasks scheduled from follow-on schedule check
[2025-06-22T01:44:34.260+0000] {local_task_job_runner.py:222} INFO - ::endgroup::
